Workbook

Sheet README
A1: Clinic Visit Data Cleanup & Dashboard
A3: A beginner-level Excel project simulating a common analyst task: taking a messy clinic visit export and turning it into a clean, reportable dashboard using formulas only (no VBA, no manually typed-in results).
A5: Tab guide
A7: Raw_Data
A8: Simulated raw export: 40 clinic visits with intentional messiness — inconsistent capitalization/spacing/punctuation in provider names, mixed-case No-Show values, and some blank/"N/A" wait times.
A10: Provider_Reference
A11: A small, clean lookup table mapping each provider to their department.
A13: Cleaned_Data
A14: Every column is a formula that reads from Raw_Data and standardizes it — nothing is typed in by hand.
A16: Dashboard
A17: Summary stats by department (total visits, no-shows, no-show rate, average wait time) plus a bar chart, all calculated live from Cleaned_Data.
A19: Techniques used
... A43: Built as part of a transition into clinical data analytics — pairing a clinical background with hands-on Excel skills (lookups, conditional logic, error handling, and summary reporting) commonly used in health-system analyst roles.

Sheet Raw_Data
A1: Visit ID | B1: Patient ID | C1: Visit Date | D1: Provider Name | E1: Visit Type | F1: No-Show | G1: Wait Time (min)
A2: V1001 | B2: P241 | C2: 45359 | D2: dr. smith | E2: New patient | F2: yes | G2: 10
A3: V1002 | B3: P248 | C3: 45358 | D3: Dr. Nguyen | E3: New patient
A4: V1003 | B4: P228 | C4: 45354 | D4: dr. smith | E4: Follow-up | F4: No | G4: 40
A5: V1004 | B5: P202 | C5: 45387 | D5: dr smith | E5: New patient | F5: No | G5: 28
A6: V1005 | B6: P215 | C6: 45380 | D6: DR PATEL | E6: Urgent | F6: Yes | G6: 50
A7: V1006 | B7: P252 | C7: 45362 | D7: dr. nguyen | E7: follow-up | F7: yes | G7: 15
A8: V1007 | B8: P249 | C8: 45373 | D8: DR SMITH | E8: Follow-up | F8: no
A9: V1008 | B9: P255 | C9: 45374 | D9: DR PATEL | E9: Urgent | F9: Yes
A10: V1009 | B10: P230 | C10: 45386 | D10: DR SMITH | E10: follow-up | F10: Yes | G10: 55
A11: V1010 | B11: P241 | C11: 45391 | D11: DR. JONES | E11: URGENT | F11: No | G11: 4
A12: V1011 | B12: P243 | C12: 45366 | D12: Dr. Jones | E12: Follow-up | F12: Yes | G12: 8
A13: V1012 | B13: P225 | C13: 45369 | D13: Dr. Patel | E13: New patient | F13: Yes | G13: 25
A14: V1013 | B14: P223 | C14: 45365 | D14: Dr. Nguyen | E14: Urgent | F14: No | G14: 43
A15: V1014 | B15: P205 | C15: 45390 | D15: Dr. Nguyen | E15: New Patient | G15: 12
A16: V1015 | B16: P230 | C16: 45376 | D16: Dr. Jones | E16: New patient | F16: No | G16: 45
A17: V1016 | B17: P221 | C17: 45355 | D17: dr smith | E17: Follow-up | F17: Yes | G17: 19
A18: V1017 | B18: P205 | C18: 45365 | D18: DR PATEL | E18: New patient | F18: yes | G18: 33
A19: V1018 | B19: P226 | C19: 45393 | D19: Dr. Patel | E19: New Patient | F19: yes | G19: N/A
A20: V1019 | B20: P248 | C20: 45387 | D20: Dr Patel | E20: Urgent | F20: No | G20: 39
A21: V1020 | B21: P226 | C21: 45375 | D21: dr smith | E21: New Patient | G21: 50
A22: V1021 | B22: P204 | C22: 45359 | D22: Dr. Smith | E22: New patient | F22: No | G22: 29
A23: V1022 | B23: P239 | C23: 45356 | D23: dr jones | E23: follow-up | G23: 35
A24: V1023 | B24: P217 | C24: 45387 | D24: dr. smith | E24: New patient | F24: No | G24: N/A
A25: V1024 | B25: P257 | C25: 45386 | D25: Dr. Jones | E25: New patient | F25: yes | G25: N/A
A26: V1025 | B26: P228 | C26: 45362 | D26: Dr. Patel | E26: Follow-up | F26: No | G26: 18
A27: V1026 | B27: P233 | C27: 45363 | D27: Dr Patel | E27: Follow-up | F27: Yes | G27: 55
A28: V1027 | B28: P241 | C28: 45384 | D28: DR PATEL | E28: New Patient | F28: No | G28: 12
A29: V1028 | B29: P235 | C29: 45385 | D29: dr. smith | E29: URGENT | F29: yes | G29: 9
A30: V1029 | B30: P260 | C30: 45375 | D30: Dr. Jones | E30: New Patient | F30: Yes | G30: 38
A31: V1030 | B31: P206 | C31: 45357 | D31: dr. nguyen | E31: follow-up | F31: Yes
A32: V1031 | B32: P249 | C32: 45386 | D32: Dr. Smith | E32: New Patient | F32: No | G32: 37
A33: V1032 | B33: P211 | C33: 45368 | D33: Dr Patel | E33: URGENT | F33: no | G33: 36
A34: V1033 | B34: P249 | C34: 45396 | D34: dr smith | E34: New patient | F34: yes | G34: 44
A35: V1034 | B35: P242 | C35: 45375 | D35: Dr. Patel | E35: URGENT | F35: no | G35: N/A
A36: V1035 | B36: P215 | C36: 45356 | D36: DR. JONES | E36: Follow-up | G36: 39
A37: V1036 | B37: P215 | C37: 45352 | D37: DR SMITH | E37: New patient | F37: No
A38: V1037 | B38: P205 | C38: 45354 | D38: DR. JONES | E38: Follow-up | G38: 44
A39: V1038 | B39: P232 | C39: 45365 | D39: Dr Patel | E39: New Patient | F39: No | G39: 38
A40: V1039 | B40: P237 | C40: 45382 | D40: dr smith | E40: follow-up | F40: Yes | G40: 8
...

Sheet Provider_Reference
A1: Provider Name (Clean) | B1: Department
A2: Dr. Smith | B2: Internal Medicine
A3: Dr. Jones | B3: Family Practice
A4: Dr. Patel | B4: Pediatrics
A5: Dr. Nguyen | B5: Cardiology
A7: This is the clean, standardized list of providers used by INDEX/MATCH in Cleaned_Data.

Sheet Cleaned_Data
A1: Visit ID | B1: Patient ID | C1: Visit Date | D1: Provider Name (Clean) | E1: Department | F1: Visit Type (Clean) | G1: No-Show (Clean) | H1: Wait Time (min)
A2: =Raw_Data!A2 -> V1001 | B2: =Raw_Data!B2 -> P241 | C2: =Raw_Data!C2 -> 45359 | D2: ="Dr. "&PROPER(TRIM(RIGHT(SUBSTITUTE(TRIM(SUBSTITUTE(Raw_Data!D2,".",""))," ",REPT(" ",100)),100))) -> Dr. Smith | E2: =IFERROR(INDEX(Provider_Reference!$B$2:$B$5,MATCH(D2,Provider_Reference!$A$2:$A$5,0)),"Check spelling") -> Internal Medicine | F2: =PROPER(Raw_Data!E2) -> New Patient | G2: =IF(LEFT(TRIM(PROPER(Raw_Data!F2)),1)="Y","Yes","No") -> Yes | H2: =IFERROR(IF(Raw_Data!G2="","",IF(ISNUMBER(Raw_Data!G2),Raw_Data!G2,"")),"") -> 10
A3: =Raw_Data!A3 -> V1002 | B3: =Raw_Data!B3 -> P248 | C3: =Raw_Data!C3 -> 45358 | D3: ="Dr. "&PROPER(TRIM(RIGHT(SUBSTITUTE(TRIM(SUBSTITUTE(Raw_Data!D3,".",""))," ",REPT(" ",100)),100))) -> Dr. Nguyen | E3: =IFERROR(INDEX(Provider_Reference!$B$2:$B$5,MATCH(D3,Provider_Reference!$A$2:$A$5,0)),"Check spelling") -> Cardiology | F3: =PROPER(Raw_Data!E3) -> New Patient | G3: =IF(LEFT(TRIM(PROPER(Raw_Data!F3)),1)="Y","Yes","No") -> No | H3: =IFERROR(IF(Raw_Data!G3="","",IF(ISNUMBER(Raw_Data!G3),Raw_Data!G3,"")),"")
A4: =Raw_Data!A4 -> V1003 | B4: =Raw_Data!B4 -> P228 | C4: =Raw_Data!C4 -> 45354 | D4: ="Dr. "&PROPER(TRIM(RIGHT(SUBSTITUTE(TRIM(SUBSTITUTE(Raw_Data!D4,".",""))," ",REPT(" ",100)),100))) -> Dr. Smith | E4: =IFERROR(INDEX(Provider_Reference!$B$2:$B$5,MATCH(D4,Provider_Reference!$A$2:$A$5,0)),"Check spelling") -> Internal Medicine | F4: =PROPER(Raw_Data!E4) -> Follow-Up | G4: =IF(LEFT(TRIM(PROPER(Raw_Data!F4)),1)="Y","Yes","No") -> No | H4: =IFERROR(IF(Raw_Data!G4="","",IF(ISNUMBER(Raw_Data!G4),Raw_Data!G4,"")),"") -> 40
A5: =Raw_Data!A5 -> V1004 | B5: =Raw_Data!B5 -> P202 | C5: =Raw_Data!C5 -> 45387 | D5: ="Dr. "&PROPER(TRIM(RIGHT(SUBSTITUTE(TRIM(SUBSTITUTE(Raw_Data!D5,".",""))," ",REPT(" ",100)),100))) -> Dr. Smith | E5: =IFERROR(INDEX(Provider_Reference!$B$2:$B$5,MATCH(D5,Provider_Reference!$A$2:$A$5,0)),"Check spelling") -> Internal Medicine | F5: =PROPER(Raw_Data!E5) -> New Patient | G5: =IF(LEFT(TRIM(PROPER(Raw_Data!F5)),1)="Y","Yes","No") -> No | H5: =IFERROR(IF(Raw_Data!G5="","",IF(ISNUMBER(Raw_Data!G5),Raw_Data!G5,"")),"") -> 28
A6: =Raw_Data!A6 -> V1005 | B6: =Raw_Data!B6 -> P215 | C6: =Raw_Data!C6 -> 45380 | D6: ="Dr. "&PROPER(TRIM(RIGHT(SUBSTITUTE(TRIM(SUBSTITUTE(Raw_Data!D6,".",""))," ",REPT(" ",100)),100))) -> Dr. Patel | E6: =IFERROR(INDEX(Provider_Reference!$B$2:$B$5,MATCH(D6,Provider_Reference!$A$2:$A$5,0)),"Check spelling") -> Pediatrics | F6: =PROPER(Raw_Data!E6) -> Urgent | G6: =IF(LEFT(TRIM(PROPER(Raw_Data!F6)),1)="Y","Yes","No") -> Yes | H6: =IFERROR(IF(Raw_Data!G6="","",IF(ISNUMBER(Raw_Data!G6),Raw_Data!G6,"")),"") -> 50
A7: =Raw_Data!A7 -> V1006 | B7: =Raw_Data!B7 -> P252 | C7: =Raw_Data!C7 -> 45362 | D7: ="Dr. "&PROPER(TRIM(RIGHT(SUBSTITUTE(TRIM(SUBSTITUTE(Raw_Data!D7,".",""))," ",REPT(" ",100)),100))) -> Dr. Nguyen | E7: =IFERROR(INDEX(Provider_Reference!$B$2:$B$5,MATCH(D7,Provider_Reference!$A$2:$A$5,0)),"Check spelling") -> Cardiology | F7: =PROPER(Raw_Data!E7) -> Follow-Up | G7: =IF(LEFT(TRIM(PROPER(Raw_Data!F7)),1)="Y","Yes","No") -> Yes | H7: =IFERROR(IF(Raw_Data!G7="","",IF(ISNUMBER(Raw_Data!G7),Raw_Data!G7,"")),"") -> 15
A8: =Raw_Data!A8 -> V1007 | B8: =Raw_Data!B8 -> P249 | C8: =Raw_Data!C8 -> 45373 | D8: ="Dr. "&PROPER(TRIM(RIGHT(SUBSTITUTE(TRIM(SUBSTITUTE(Raw_Data!D8,".",""))," ",REPT(" ",100)),100))) -> Dr. Smith | E8: =IFERROR(INDEX(Provider_Reference!$B$2:$B$5,MATCH(D8,Provider_Reference!$A$2:$A$5,0)),"Check spelling") -> Internal Medicine | F8: =PROPER(Raw_Data!E8) -> Follow-Up | G8: =IF(LEFT(TRIM(PROPER(Raw_Data!F8)),1)="Y","Yes","No") -> No | H8: =IFERROR(IF(Raw_Data!G8="","",IF(ISNUMBER(Raw_Data!G8),Raw_Data!G8,"")),"")
A9: =Raw_Data!A9 -> V1008 | B9: =Raw_Data!B9 -> P255 | C9: =Raw_Data!C9 -> 45374 | D9: ="Dr. "&PROPER(TRIM(RIGHT(SUBSTITUTE(TRIM(SUBSTITUTE(Raw_Data!D9,".",""))," ",REPT(" ",100)),100))) -> Dr. Patel | E9: =IFERROR(INDEX(Provider_Reference!$B$2:$B$5,MATCH(D9,Provider_Reference!$A$2:$A$5,0)),"Check spelling") -> Pediatrics | F9: =PROPER(Raw_Data!E9) -> Urgent | G9: =IF(LEFT(TRIM(PROPER(Raw_Data!F9)),1)="Y","Yes","No") -> Yes | H9: =IFERROR(IF(Raw_Data!G9="","",IF(ISNUMBER(Raw_Data!G9),Raw_Data!G9,"")),"")
A10: =Raw_Data!A10 -> V1009 | B10: =Raw_Data!B10 -> P230 | C10: =Raw_Data!C10 -> 45386 | D10: ="Dr. "&PROPER(TRIM(RIGHT(SUBSTITUTE(TRIM(SUBSTITUTE(Raw_Data!D10,".",""))," ",REPT(" ",100)),100))) -> Dr. Smith | E10: =IFERROR(INDEX(Provider_Reference!$B$2:$B$5,MATCH(D10,Provider_Reference!$A$2:$A$5,0)),"Check spelling") -> Internal Medicine | F10: =PROPER(Raw_Data!E10) -> Follow-Up | G10: =IF(LEFT(TRIM(PROPER(Raw_Data!F10)),1)="Y","Yes","No") -> Yes | H10: =IFERROR(IF(Raw_Data!G10="","",IF(ISNUMBER(Raw_Data!G10),Raw_Data!G10,"")),"") -> 55
A11: =Raw_Data!A11 -> V1010 | B11: =Raw_Data!B11 -> P241 | C11: =Raw_Data!C11 -> 45391 | D11: ="Dr. "&PROPER(TRIM(RIGHT(SUBSTITUTE(TRIM(SUBSTITUTE(Raw_Data!D11,".",""))," ",REPT(" ",100)),100))) -> Dr. Jones | E11: =IFERROR(INDEX(Provider_Reference!$B$2:$B$5,MATCH(D11,Provider_Reference!$A$2:$A$5,0)),"Check spelling") -> Family Practice | F11: =PROPER(Raw_Data!E11) -> Urgent | G11: =IF(LEFT(TRIM(PROPER(Raw_Data!F11)),1)="Y","Yes","No") -> No | H11: =IFERROR(IF(Raw_Data!G11="","",IF(ISNUMBER(Raw_Data!G11),Raw_Data!G11,"")),"") -> 4
A12: =Raw_Data!A12 -> V1011 | B12: =Raw_Data!B12 -> P243 | C12: =Raw_Data!C12 -> 45366 | D12: ="Dr. "&PROPER(TRIM(RIGHT(SUBSTITUTE(TRIM(SUBSTITUTE(Raw_Data!D12,".",""))," ",REPT(" ",100)),100))) -> Dr. Jones | E12: =IFERROR(INDEX(Provider_Reference!$B$2:$B$5,MATCH(D12,Provider_Reference!$A$2:$A$5,0)),"Check spelling") -> Family Practice | F12: =PROPER(Raw_Data!E12) -> Follow-Up | G12: =IF(LEFT(TRIM(PROPER(Raw_Data!F12)),1)="Y","Yes","No") -> Yes | H12: =IFERROR(IF(Raw_Data!G12="","",IF(ISNUMBER(Raw_Data!G12),Raw_Data!G12,"")),"") -> 8
A13: =Raw_Data!A13 -> V1012 | B13: =Raw_Data!B13 -> P225 | C13: =Raw_Data!C13 -> 45369 | D13: ="Dr. "&PROPER(TRIM(RIGHT(SUBSTITUTE(TRIM(SUBSTITUTE(Raw_Data!D13,".",""))," ",REPT(" ",100)),100))) -> Dr. Patel | E13: =IFERROR(INDEX(Provider_Reference!$B$2:$B$5,MATCH(D13,Provider_Reference!$A$2:$A$5,0)),"Check spelling") -> Pediatrics | F13: =PROPER(Raw_Data!E13) -> New Patient | G13: =IF(LEFT(TRIM(PROPER(Raw_Data!F13)),1)="Y","Yes","No") -> Yes | H13: =IFERROR(IF(Raw_Data!G13="","",IF(ISNUMBER(Raw_Data!G13),Raw_Data!G13,"")),"") -> 25
... A41: =Raw_Data!A41 -> V1040 | B41: =Raw_Data!B41 -> P207 | C41: =Raw_Data!C41 -> 45394 | D41: ="Dr. "&PROPER(TRIM(RIGHT(SUBSTITUTE(TRIM(SUBSTITUTE(Raw_Data!D41,".",""))," ",REPT(" ",100)),100))) -> Dr. Jones | E41: =IFERROR(INDEX(Provider_Reference!$B$2:$B$5,MATCH(D41,Provider_Reference!$A$2:$A$5,0)),"Check spelling") -> Family Practice | F41: =PROPER(Raw_Data!E41) -> Urgent | G41: =IF(LEFT(TRIM(PROPER(Raw_Data!F41)),1)="Y","Yes","No") -> No | H41: =IFERROR(IF(Raw_Data!G41="","",IF(ISNUMBER(Raw_Data!G41),Raw_Data!G41,"")),"") -> 48
A44: Every column here is a formula that reads from Raw_Data — nothing is typed in by hand. That way if Raw_Data changes, this tab (and the dashboard) updates automatically.

Sheet Dashboard
A1: Clinic Visit Summary Dashboard
A3: By Department
A4: Department | B4: Total Visits | C4: No-Shows | D4: No-Show Rate | E4: Avg Wait Time (min)
A5: Internal Medicine | B5: =COUNTIF(Cleaned_Data!$E$2:$E$41,A5) -> 14 | C5: =COUNTIFS(Cleaned_Data!$E$2:$E$41,A5,Cleaned_Data!$G$2:$G$41,"Yes") -> 6 | D5: =IFERROR(C5/B5,0) -> 0.42857143 | E5: =IFERROR(AVERAGEIFS(Cleaned_Data!$H$2:$H$41,Cleaned_Data!$E$2:$E$41,A5),0) -> 29.909091
A6: Family Practice | B6: =COUNTIF(Cleaned_Data!$E$2:$E$41,A6) -> 9 | C6: =COUNTIFS(Cleaned_Data!$E$2:$E$41,A6,Cleaned_Data!$G$2:$G$41,"Yes") -> 3 | D6: =IFERROR(C6/B6,0) -> 0.33333333 | E6: =IFERROR(AVERAGEIFS(Cleaned_Data!$H$2:$H$41,Cleaned_Data!$E$2:$E$41,A6),0) -> 32.625
A7: Pediatrics | B7: =COUNTIF(Cleaned_Data!$E$2:$E$41,A7) -> 12 | C7: =COUNTIFS(Cleaned_Data!$E$2:$E$41,A7,Cleaned_Data!$G$2:$G$41,"Yes") -> 6 | D7: =IFERROR(C7/B7,0) -> 0.5 | E7: =IFERROR(AVERAGEIFS(Cleaned_Data!$H$2:$H$41,Cleaned_Data!$E$2:$E$41,A7),0) -> 34
A8: Cardiology | B8: =COUNTIF(Cleaned_Data!$E$2:$E$41,A8) -> 5 | C8: =COUNTIFS(Cleaned_Data!$E$2:$E$41,A8,Cleaned_Data!$G$2:$G$41,"Yes") -> 2 | D8: =IFERROR(C8/B8,0) -> 0.4 | E8: =IFERROR(AVERAGEIFS(Cleaned_Data!$H$2:$H$41,Cleaned_Data!$E$2:$E$41,A8),0) -> 23.333333
A9: Total / Overall | B9: =SUM(B5:B8) -> 40 | C9: =SUM(C5:C8) -> 17 | D9: =IFERROR(C9/B9,0) -> 0.425 | E9: =IFERROR(AVERAGE(Cleaned_Data!$H$2:$H$41),0) -> 31.16129
A11: All figures are formulas (COUNTIF/COUNTIFS/AVERAGEIFS) pulling live from Cleaned_Data.
